# 2022-03-07 19:09:25.575290: W tensorflow/stream_executor/platform/default/dso_loader.cc:64] Could not load dynamic library 'libcudart.so.11.0'; dlerror: libcudart.so.11.0: cannot open shared object file: No such file or directory2022-03-07 19:09:25.575344: I tensorflow/stream_executor/cuda/cudart_stub.cc:29] Ignore above cudart dlerror if you do not have a GPU set up on your machine.2022-03-07 19:09:26.484434: W tensorflow/stream_executor/platform/default/dso_loader.cc:64] Could not load dynamic library 'libcuda.so.1'; dlerror: libcuda.so.1: cannot open shared object file: No such file or directory2022-03-07 19:09:26.484495: W tensorflow/stream_executor/cuda/cuda_driver.cc:269] failed call to cuInit: UNKNOWN ERROR (303)2022-03-07 19:09:26.484517: I tensorflow/stream_executor/cuda/cuda_diagnostics.cc:156] kernel driver does not appear to be running on this host (devel): /proc/driver/nvidia/version does not exist2022-03-07 19:09:26.484805: I tensorflow/core/platform/cpu_feature_guard.cc:151] This TensorFlow binary is optimized with oneAPI Deep Neural Network Library (oneDNN) to use the following CPU instructions in performance-critical operations:  AVX2 AVX512F FMATo enable them in other operations, rebuild TensorFlow with the appropriate compiler flags.2022-03-07 19:09:26.488809: W tensorflow/core/framework/op_kernel.cc:1745] OP_REQUIRES failed at spacetobatch_op.cc:219 : INVALID_ARGUMENT: block_shape rank should be 1 instead of 0Traceback (most recent call last):  File "/media/ivysyn/tensorflow/synthesized/all-crashes/all/SpaceToBatchND_d0c13c1f5a4cf9f52134d2b37dada7a4.py", line 8, in <module>    tf.raw_ops.SpaceToBatchND(input=input, block_shape=block_shape, paddings=paddings)  File "/home/neo/.local/lib/python3.9/site-packages/tensorflow/python/util/tf_export.py", line 400, in wrapper    return f(**kwargs)  File "/home/neo/.local/lib/python3.9/site-packages/tensorflow/python/ops/gen_array_ops.py", line 9966, in space_to_batch_nd    _ops.raise_from_not_ok_status(e, name)  File "/home/neo/.local/lib/python3.9/site-packages/tensorflow/python/framework/ops.py", line 7186, in raise_from_not_ok_status    raise core._status_to_exception(e) from None  # pylint: disable=protected-accesstensorflow.python.framework.errors_impl.InvalidArgumentError: block_shape rank should be 1 instead of 0 [Op:SpaceToBatchND]

# SpaceToBatchNDOp

import tensorflow as tf

input = tf.constant(-3.5e+35, shape=[10,19,22], dtype=tf.float32)
block_shape = tf.constant(65534, shape=[], dtype=tf.int32)
paddings = tf.constant(0, shape=[2,2], dtype=tf.int32)
tf.raw_ops.SpaceToBatchND(input=input, block_shape=block_shape, paddings=paddings)